2022-04-23 17:37:26,233 INFO    MainThread:29213 [internal.py:wandb_internal():86] W&B internal server running at pid: 29213, started at: 2022-04-23 17:37:26.233121
2022-04-23 17:37:26,235 DEBUG   HandlerThread:29213 [handler.py:handle_request():126] handle_request: check_version
2022-04-23 17:37:26,236 INFO    WriterThread:29213 [datastore.py:open_for_write():77] open: /home/fateme/Desktop/DeepLearning/fashionMnistTorch/wandb/run-20220423_173725-39a282ud/run-39a282ud.wandb
2022-04-23 17:37:26,238 DEBUG   SenderThread:29213 [sender.py:send():182] send: header
2022-04-23 17:37:26,238 DEBUG   SenderThread:29213 [sender.py:send_request():196] send_request: check_version
2022-04-23 17:37:26,904 DEBUG   SenderThread:29213 [sender.py:send():182] send: run
2022-04-23 17:37:27,455 ERROR   SenderThread:29213 [internal_api.py:execute():133] 403 response executing GraphQL.
2022-04-23 17:37:27,457 ERROR   SenderThread:29213 [internal_api.py:execute():134] 
<html><head>
<meta http-equiv="content-type" content="text/html;charset=utf-8">
<title>403 Forbidden</title>
</head>
<body text=#000000 bgcolor=#ffffff>
<h1>Error: Forbidden</h1>
<h2>Your client does not have permission to get URL <code>/graphql</code> from this server.</h2>
<h2></h2>
</body></html>

2022-04-23 17:37:27,905 INFO    HandlerThread:29213 [handler.py:finish():683] shutting down handler
2022-04-23 17:37:27,906 INFO    WriterThread:29213 [datastore.py:close():281] close: /home/fateme/Desktop/DeepLearning/fashionMnistTorch/wandb/run-20220423_173725-39a282ud/run-39a282ud.wandb
2022-04-23 17:37:28,238 ERROR   MainThread:29213 [internal.py:wandb_internal():157] Thread SenderThread:
Traceback (most recent call last):
  File "/home/fateme/.local/lib/python3.8/site-packages/wandb/sdk/lib/retry.py", line 102, in __call__
    result = self._call_fn(*args, **kwargs)
  File "/home/fateme/.local/lib/python3.8/site-packages/wandb/sdk/internal/internal_api.py", line 136, in execute
    six.reraise(*sys.exc_info())
  File "/home/fateme/.local/lib/python3.8/site-packages/six.py", line 703, in reraise
    raise value
  File "/home/fateme/.local/lib/python3.8/site-packages/wandb/sdk/internal/internal_api.py", line 130, in execute
    return self.client.execute(*args, **kwargs)
  File "/home/fateme/.local/lib/python3.8/site-packages/wandb/vendor/gql-0.2.0/gql/client.py", line 52, in execute
    result = self._get_result(document, *args, **kwargs)
  File "/home/fateme/.local/lib/python3.8/site-packages/wandb/vendor/gql-0.2.0/gql/client.py", line 60, in _get_result
    return self.transport.execute(document, *args, **kwargs)
  File "/home/fateme/.local/lib/python3.8/site-packages/wandb/vendor/gql-0.2.0/gql/transport/requests.py", line 39, in execute
    request.raise_for_status()
  File "/usr/lib/python3/dist-packages/requests/models.py", line 940, in raise_for_status
    raise HTTPError(http_error_msg, response=self)
requests.exceptions.HTTPError: 403 Client Error: Forbidden for url: https://api.wandb.ai/graphql

During handling of the above exception, another exception occurred:

Traceback (most recent call last):
  File "/home/fateme/.local/lib/python3.8/site-packages/wandb/apis/normalize.py", line 24, in wrapper
    return func(*args, **kwargs)
  File "/home/fateme/.local/lib/python3.8/site-packages/wandb/sdk/internal/internal_api.py", line 1087, in upsert_run
    response = self.gql(mutation, variable_values=variable_values, **kwargs)
  File "/home/fateme/.local/lib/python3.8/site-packages/wandb/sdk/lib/retry.py", line 118, in __call__
    if not check_retry_fn(e):
  File "/home/fateme/.local/lib/python3.8/site-packages/wandb/util.py", line 809, in no_retry_auth
    raise CommError("Permission denied, ask the project owner to grant you access")
wandb.errors.CommError: Permission denied, ask the project owner to grant you access

During handling of the above exception, another exception occurred:

Traceback (most recent call last):
  File "/home/fateme/.local/lib/python3.8/site-packages/wandb/sdk/internal/internal_util.py", line 52, in run
    self._run()
  File "/home/fateme/.local/lib/python3.8/site-packages/wandb/sdk/internal/internal_util.py", line 102, in _run
    self._process(record)
  File "/home/fateme/.local/lib/python3.8/site-packages/wandb/sdk/internal/internal.py", line 290, in _process
    self._sm.send(record)
  File "/home/fateme/.local/lib/python3.8/site-packages/wandb/sdk/internal/sender.py", line 184, in send
    send_handler(record)
  File "/home/fateme/.local/lib/python3.8/site-packages/wandb/sdk/internal/sender.py", line 623, in send_run
    self._init_run(run, config_value_dict)
  File "/home/fateme/.local/lib/python3.8/site-packages/wandb/sdk/internal/sender.py", line 645, in _init_run
    server_run, inserted = self._api.upsert_run(
  File "/home/fateme/.local/lib/python3.8/site-packages/wandb/apis/normalize.py", line 62, in wrapper
    six.reraise(CommError, CommError(message, err), sys.exc_info()[2])
  File "/home/fateme/.local/lib/python3.8/site-packages/six.py", line 702, in reraise
    raise value.with_traceback(tb)
  File "/home/fateme/.local/lib/python3.8/site-packages/wandb/apis/normalize.py", line 24, in wrapper
    return func(*args, **kwargs)
  File "/home/fateme/.local/lib/python3.8/site-packages/wandb/sdk/internal/internal_api.py", line 1087, in upsert_run
    response = self.gql(mutation, variable_values=variable_values, **kwargs)
  File "/home/fateme/.local/lib/python3.8/site-packages/wandb/sdk/lib/retry.py", line 118, in __call__
    if not check_retry_fn(e):
  File "/home/fateme/.local/lib/python3.8/site-packages/wandb/util.py", line 809, in no_retry_auth
    raise CommError("Permission denied, ask the project owner to grant you access")
wandb.errors.CommError: Permission denied, ask the project owner to grant you access
2022-04-23 17:37:30,298 INFO    MainThread:29213 [internal.py:handle_exit():76] Internal process exited
